2025-03-20 09:28:22,712 - ERROR - Exception occurred: Traceback (most recent call last):
  File "C:\Users\VINIL\AppData\Local\Temp\ipykernel_2056\3486708776.py", line 33, in <module>
    df = pd.read_csv(dataset_path)
         ^^^^^^^^^^^^^^^^^^^^^^^^^
  File "c:\Users\VINIL\AppData\Local\Programs\Python\Python312\Lib\site-packages\pandas\io\parsers\readers.py", line 1026, in read_csv
    return _read(filepath_or_buffer, kwds)
           ^^^^^^^^^^^^^^^^^^^^^^^^^^^^^^^
  File "c:\Users\VINIL\AppData\Local\Programs\Python\Python312\Lib\site-packages\pandas\io\parsers\readers.py", line 620, in _read
    parser = TextFileReader(filepath_or_buffer, **kwds)
             ^^^^^^^^^^^^^^^^^^^^^^^^^^^^^^^^^^^^^^^^^^
  File "c:\Users\VINIL\AppData\Local\Programs\Python\Python312\Lib\site-packages\pandas\io\parsers\readers.py", line 1620, in __init__
    self._engine = self._make_engine(f, self.engine)
                   ^^^^^^^^^^^^^^^^^^^^^^^^^^^^^^^^^
  File "c:\Users\VINIL\AppData\Local\Programs\Python\Python312\Lib\site-packages\pandas\io\parsers\readers.py", line 1880, in _make_engine
    self.handles = get_handle(
                   ^^^^^^^^^^^
  File "c:\Users\VINIL\AppData\Local\Programs\Python\Python312\Lib\site-packages\pandas\io\common.py", line 873, in get_handle
    handle = open(
             ^^^^^
FileNotFoundError: [Errno 2] No such file or directory: 'India_Crop_Price_Prediction_Dataset.csv'

2025-03-20 09:28:24,653 - ERROR - Exception occurred: Traceback (most recent call last):
  File "C:\Users\VINIL\AppData\Local\Temp\ipykernel_2056\3486708776.py", line 33, in <module>
    df = pd.read_csv(dataset_path)
         ^^^^^^^^^^^^^^^^^^^^^^^^^
  File "c:\Users\VINIL\AppData\Local\Programs\Python\Python312\Lib\site-packages\pandas\io\parsers\readers.py", line 1026, in read_csv
    return _read(filepath_or_buffer, kwds)
           ^^^^^^^^^^^^^^^^^^^^^^^^^^^^^^^
  File "c:\Users\VINIL\AppData\Local\Programs\Python\Python312\Lib\site-packages\pandas\io\parsers\readers.py", line 620, in _read
    parser = TextFileReader(filepath_or_buffer, **kwds)
             ^^^^^^^^^^^^^^^^^^^^^^^^^^^^^^^^^^^^^^^^^^
  File "c:\Users\VINIL\AppData\Local\Programs\Python\Python312\Lib\site-packages\pandas\io\parsers\readers.py", line 1620, in __init__
    self._engine = self._make_engine(f, self.engine)
                   ^^^^^^^^^^^^^^^^^^^^^^^^^^^^^^^^^
  File "c:\Users\VINIL\AppData\Local\Programs\Python\Python312\Lib\site-packages\pandas\io\parsers\readers.py", line 1880, in _make_engine
    self.handles = get_handle(
                   ^^^^^^^^^^^
  File "c:\Users\VINIL\AppData\Local\Programs\Python\Python312\Lib\site-packages\pandas\io\common.py", line 873, in get_handle
    handle = open(
             ^^^^^
FileNotFoundError: [Errno 2] No such file or directory: 'India_Crop_Price_Prediction_Dataset.csv'

2025-03-20 09:28:26,163 - ERROR - Exception occurred: Traceback (most recent call last):
  File "C:\Users\VINIL\AppData\Local\Temp\ipykernel_2056\3486708776.py", line 33, in <module>
    df = pd.read_csv(dataset_path)
         ^^^^^^^^^^^^^^^^^^^^^^^^^
  File "c:\Users\VINIL\AppData\Local\Programs\Python\Python312\Lib\site-packages\pandas\io\parsers\readers.py", line 1026, in read_csv
    return _read(filepath_or_buffer, kwds)
           ^^^^^^^^^^^^^^^^^^^^^^^^^^^^^^^
  File "c:\Users\VINIL\AppData\Local\Programs\Python\Python312\Lib\site-packages\pandas\io\parsers\readers.py", line 620, in _read
    parser = TextFileReader(filepath_or_buffer, **kwds)
             ^^^^^^^^^^^^^^^^^^^^^^^^^^^^^^^^^^^^^^^^^^
  File "c:\Users\VINIL\AppData\Local\Programs\Python\Python312\Lib\site-packages\pandas\io\parsers\readers.py", line 1620, in __init__
    self._engine = self._make_engine(f, self.engine)
                   ^^^^^^^^^^^^^^^^^^^^^^^^^^^^^^^^^
  File "c:\Users\VINIL\AppData\Local\Programs\Python\Python312\Lib\site-packages\pandas\io\parsers\readers.py", line 1880, in _make_engine
    self.handles = get_handle(
                   ^^^^^^^^^^^
  File "c:\Users\VINIL\AppData\Local\Programs\Python\Python312\Lib\site-packages\pandas\io\common.py", line 873, in get_handle
    handle = open(
             ^^^^^
FileNotFoundError: [Errno 2] No such file or directory: 'India_Crop_Price_Prediction_Dataset.csv'

2025-03-20 09:28:31,272 - ERROR - Exception occurred: Traceback (most recent call last):
  File "C:\Users\VINIL\AppData\Local\Temp\ipykernel_2056\3486708776.py", line 33, in <module>
    df = pd.read_csv(dataset_path)
         ^^^^^^^^^^^^^^^^^^^^^^^^^
  File "c:\Users\VINIL\AppData\Local\Programs\Python\Python312\Lib\site-packages\pandas\io\parsers\readers.py", line 1026, in read_csv
    return _read(filepath_or_buffer, kwds)
           ^^^^^^^^^^^^^^^^^^^^^^^^^^^^^^^
  File "c:\Users\VINIL\AppData\Local\Programs\Python\Python312\Lib\site-packages\pandas\io\parsers\readers.py", line 620, in _read
    parser = TextFileReader(filepath_or_buffer, **kwds)
             ^^^^^^^^^^^^^^^^^^^^^^^^^^^^^^^^^^^^^^^^^^
  File "c:\Users\VINIL\AppData\Local\Programs\Python\Python312\Lib\site-packages\pandas\io\parsers\readers.py", line 1620, in __init__
    self._engine = self._make_engine(f, self.engine)
                   ^^^^^^^^^^^^^^^^^^^^^^^^^^^^^^^^^
  File "c:\Users\VINIL\AppData\Local\Programs\Python\Python312\Lib\site-packages\pandas\io\parsers\readers.py", line 1880, in _make_engine
    self.handles = get_handle(
                   ^^^^^^^^^^^
  File "c:\Users\VINIL\AppData\Local\Programs\Python\Python312\Lib\site-packages\pandas\io\common.py", line 873, in get_handle
    handle = open(
             ^^^^^
FileNotFoundError: [Errno 2] No such file or directory: 'India_Crop_Price_Prediction_Dataset.csv'

2025-03-20 09:28:38,413 - ERROR - Exception occurred: Traceback (most recent call last):
  File "C:\Users\VINIL\AppData\Local\Temp\ipykernel_2056\3486708776.py", line 33, in <module>
    df = pd.read_csv(dataset_path)
         ^^^^^^^^^^^^^^^^^^^^^^^^^
  File "c:\Users\VINIL\AppData\Local\Programs\Python\Python312\Lib\site-packages\pandas\io\parsers\readers.py", line 1026, in read_csv
    return _read(filepath_or_buffer, kwds)
           ^^^^^^^^^^^^^^^^^^^^^^^^^^^^^^^
  File "c:\Users\VINIL\AppData\Local\Programs\Python\Python312\Lib\site-packages\pandas\io\parsers\readers.py", line 620, in _read
    parser = TextFileReader(filepath_or_buffer, **kwds)
             ^^^^^^^^^^^^^^^^^^^^^^^^^^^^^^^^^^^^^^^^^^
  File "c:\Users\VINIL\AppData\Local\Programs\Python\Python312\Lib\site-packages\pandas\io\parsers\readers.py", line 1620, in __init__
    self._engine = self._make_engine(f, self.engine)
                   ^^^^^^^^^^^^^^^^^^^^^^^^^^^^^^^^^
  File "c:\Users\VINIL\AppData\Local\Programs\Python\Python312\Lib\site-packages\pandas\io\parsers\readers.py", line 1880, in _make_engine
    self.handles = get_handle(
                   ^^^^^^^^^^^
  File "c:\Users\VINIL\AppData\Local\Programs\Python\Python312\Lib\site-packages\pandas\io\common.py", line 873, in get_handle
    handle = open(
             ^^^^^
FileNotFoundError: [Errno 2] No such file or directory: 'India_Crop_Price_Prediction_Dataset.csv'

2025-03-20 09:28:43,104 - ERROR - Exception occurred: Traceback (most recent call last):
  File "C:\Users\VINIL\AppData\Local\Temp\ipykernel_2056\3486708776.py", line 33, in <module>
    df = pd.read_csv(dataset_path)
         ^^^^^^^^^^^^^^^^^^^^^^^^^
  File "c:\Users\VINIL\AppData\Local\Programs\Python\Python312\Lib\site-packages\pandas\io\parsers\readers.py", line 1026, in read_csv
    return _read(filepath_or_buffer, kwds)
           ^^^^^^^^^^^^^^^^^^^^^^^^^^^^^^^
  File "c:\Users\VINIL\AppData\Local\Programs\Python\Python312\Lib\site-packages\pandas\io\parsers\readers.py", line 620, in _read
    parser = TextFileReader(filepath_or_buffer, **kwds)
             ^^^^^^^^^^^^^^^^^^^^^^^^^^^^^^^^^^^^^^^^^^
  File "c:\Users\VINIL\AppData\Local\Programs\Python\Python312\Lib\site-packages\pandas\io\parsers\readers.py", line 1620, in __init__
    self._engine = self._make_engine(f, self.engine)
                   ^^^^^^^^^^^^^^^^^^^^^^^^^^^^^^^^^
  File "c:\Users\VINIL\AppData\Local\Programs\Python\Python312\Lib\site-packages\pandas\io\parsers\readers.py", line 1880, in _make_engine
    self.handles = get_handle(
                   ^^^^^^^^^^^
  File "c:\Users\VINIL\AppData\Local\Programs\Python\Python312\Lib\site-packages\pandas\io\common.py", line 873, in get_handle
    handle = open(
             ^^^^^
FileNotFoundError: [Errno 2] No such file or directory: 'India_Crop_Price_Prediction_Dataset.csv'

2025-03-20 09:28:43,921 - ERROR - Exception occurred: Traceback (most recent call last):
  File "C:\Users\VINIL\AppData\Local\Temp\ipykernel_2056\3486708776.py", line 33, in <module>
    df = pd.read_csv(dataset_path)
         ^^^^^^^^^^^^^^^^^^^^^^^^^
  File "c:\Users\VINIL\AppData\Local\Programs\Python\Python312\Lib\site-packages\pandas\io\parsers\readers.py", line 1026, in read_csv
    return _read(filepath_or_buffer, kwds)
           ^^^^^^^^^^^^^^^^^^^^^^^^^^^^^^^
  File "c:\Users\VINIL\AppData\Local\Programs\Python\Python312\Lib\site-packages\pandas\io\parsers\readers.py", line 620, in _read
    parser = TextFileReader(filepath_or_buffer, **kwds)
             ^^^^^^^^^^^^^^^^^^^^^^^^^^^^^^^^^^^^^^^^^^
  File "c:\Users\VINIL\AppData\Local\Programs\Python\Python312\Lib\site-packages\pandas\io\parsers\readers.py", line 1620, in __init__
    self._engine = self._make_engine(f, self.engine)
                   ^^^^^^^^^^^^^^^^^^^^^^^^^^^^^^^^^
  File "c:\Users\VINIL\AppData\Local\Programs\Python\Python312\Lib\site-packages\pandas\io\parsers\readers.py", line 1880, in _make_engine
    self.handles = get_handle(
                   ^^^^^^^^^^^
  File "c:\Users\VINIL\AppData\Local\Programs\Python\Python312\Lib\site-packages\pandas\io\common.py", line 873, in get_handle
    handle = open(
             ^^^^^
FileNotFoundError: [Errno 2] No such file or directory: 'India_Crop_Price_Prediction_Dataset.csv'

2025-03-20 09:28:44,102 - ERROR - Exception occurred: Traceback (most recent call last):
  File "C:\Users\VINIL\AppData\Local\Temp\ipykernel_2056\3486708776.py", line 33, in <module>
    df = pd.read_csv(dataset_path)
         ^^^^^^^^^^^^^^^^^^^^^^^^^
  File "c:\Users\VINIL\AppData\Local\Programs\Python\Python312\Lib\site-packages\pandas\io\parsers\readers.py", line 1026, in read_csv
    return _read(filepath_or_buffer, kwds)
           ^^^^^^^^^^^^^^^^^^^^^^^^^^^^^^^
  File "c:\Users\VINIL\AppData\Local\Programs\Python\Python312\Lib\site-packages\pandas\io\parsers\readers.py", line 620, in _read
    parser = TextFileReader(filepath_or_buffer, **kwds)
             ^^^^^^^^^^^^^^^^^^^^^^^^^^^^^^^^^^^^^^^^^^
  File "c:\Users\VINIL\AppData\Local\Programs\Python\Python312\Lib\site-packages\pandas\io\parsers\readers.py", line 1620, in __init__
    self._engine = self._make_engine(f, self.engine)
                   ^^^^^^^^^^^^^^^^^^^^^^^^^^^^^^^^^
  File "c:\Users\VINIL\AppData\Local\Programs\Python\Python312\Lib\site-packages\pandas\io\parsers\readers.py", line 1880, in _make_engine
    self.handles = get_handle(
                   ^^^^^^^^^^^
  File "c:\Users\VINIL\AppData\Local\Programs\Python\Python312\Lib\site-packages\pandas\io\common.py", line 873, in get_handle
    handle = open(
             ^^^^^
FileNotFoundError: [Errno 2] No such file or directory: 'India_Crop_Price_Prediction_Dataset.csv'

2025-03-20 09:28:44,317 - ERROR - Exception occurred: Traceback (most recent call last):
  File "C:\Users\VINIL\AppData\Local\Temp\ipykernel_2056\3486708776.py", line 33, in <module>
    df = pd.read_csv(dataset_path)
         ^^^^^^^^^^^^^^^^^^^^^^^^^
  File "c:\Users\VINIL\AppData\Local\Programs\Python\Python312\Lib\site-packages\pandas\io\parsers\readers.py", line 1026, in read_csv
    return _read(filepath_or_buffer, kwds)
           ^^^^^^^^^^^^^^^^^^^^^^^^^^^^^^^
  File "c:\Users\VINIL\AppData\Local\Programs\Python\Python312\Lib\site-packages\pandas\io\parsers\readers.py", line 620, in _read
    parser = TextFileReader(filepath_or_buffer, **kwds)
             ^^^^^^^^^^^^^^^^^^^^^^^^^^^^^^^^^^^^^^^^^^
  File "c:\Users\VINIL\AppData\Local\Programs\Python\Python312\Lib\site-packages\pandas\io\parsers\readers.py", line 1620, in __init__
    self._engine = self._make_engine(f, self.engine)
                   ^^^^^^^^^^^^^^^^^^^^^^^^^^^^^^^^^
  File "c:\Users\VINIL\AppData\Local\Programs\Python\Python312\Lib\site-packages\pandas\io\parsers\readers.py", line 1880, in _make_engine
    self.handles = get_handle(
                   ^^^^^^^^^^^
  File "c:\Users\VINIL\AppData\Local\Programs\Python\Python312\Lib\site-packages\pandas\io\common.py", line 873, in get_handle
    handle = open(
             ^^^^^
FileNotFoundError: [Errno 2] No such file or directory: 'India_Crop_Price_Prediction_Dataset.csv'

2025-03-20 09:29:09,608 - ERROR - Exception occurred: Traceback (most recent call last):
  File "C:\Users\VINIL\AppData\Local\Temp\ipykernel_2056\888268746.py", line 33, in <module>
    df = pd.read_csv(dataset_path)
         ^^^^^^^^^^^^^^^^^^^^^^^^^
  File "c:\Users\VINIL\AppData\Local\Programs\Python\Python312\Lib\site-packages\pandas\io\parsers\readers.py", line 1026, in read_csv
    return _read(filepath_or_buffer, kwds)
           ^^^^^^^^^^^^^^^^^^^^^^^^^^^^^^^
  File "c:\Users\VINIL\AppData\Local\Programs\Python\Python312\Lib\site-packages\pandas\io\parsers\readers.py", line 620, in _read
    parser = TextFileReader(filepath_or_buffer, **kwds)
             ^^^^^^^^^^^^^^^^^^^^^^^^^^^^^^^^^^^^^^^^^^
  File "c:\Users\VINIL\AppData\Local\Programs\Python\Python312\Lib\site-packages\pandas\io\parsers\readers.py", line 1620, in __init__
    self._engine = self._make_engine(f, self.engine)
                   ^^^^^^^^^^^^^^^^^^^^^^^^^^^^^^^^^
  File "c:\Users\VINIL\AppData\Local\Programs\Python\Python312\Lib\site-packages\pandas\io\parsers\readers.py", line 1880, in _make_engine
    self.handles = get_handle(
                   ^^^^^^^^^^^
  File "c:\Users\VINIL\AppData\Local\Programs\Python\Python312\Lib\site-packages\pandas\io\common.py", line 873, in get_handle
    handle = open(
             ^^^^^
FileNotFoundError: [Errno 2] No such file or directory: 'India_Crop_Price_Prediction_Dataset.csv'

2025-03-20 09:31:41,481 - INFO - Dataset loaded successfully.
2025-03-20 09:31:41,485 - INFO - Features and target variable separated.
2025-03-20 09:31:41,485 - INFO - Categorical columns: ['Crop', 'Region']
2025-03-20 09:31:41,485 - INFO - Numerical columns: ['Year', 'Rainfall_mm', 'Avg_Temperature_C', 'Production_Tonnes', 'MSP', 'Export_Demand_Tonnes', 'Prev_Year_Price']
2025-03-20 09:31:41,487 - INFO - Data split into training and testing sets.
2025-03-20 09:31:43,022 - INFO - Random Forest Regression model trained and predictions made.
2025-03-20 09:31:43,023 - INFO - Random Forest Regression - R2: 0.9251, MAE: 182.9036, MSE: 51062.7422, RMSE: 225.9707
2025-03-20 09:31:43,037 - INFO - Random Forest Regression - Regression confusion matrix:
Predicted Bin   0   1   2   3   4
Actual Bin                       
0              50   9   0   0   0
1               1  82  12   0   0
2               0   8  33  22   0
3               0   0   9  33  19
4               0   0   0  11  19
2025-03-20 09:31:43,037 - INFO - All evaluations and plots completed successfully.
2025-03-20 09:31:53,687 - INFO - Random Forest Regression pipeline saved successfully at: C:\Users\VINIL\Desktop\Market_price_ML\flask_app\models\random_forest_pipeline.pkl
2025-03-20 09:34:21,490 - ERROR - Exception occurred: Traceback (most recent call last):
  File "C:\Users\VINIL\AppData\Local\Temp\ipykernel_2056\2265069806.py", line 33, in <module>
    pickle.dump(rf_model, model_file)
                ^^^^^^^^
NameError: name 'rf_model' is not defined

2025-03-20 12:52:53,548 - INFO - Dataset loaded successfully.
2025-03-20 12:52:53,562 - INFO - Features and target variable separated.
2025-03-20 12:52:53,562 - INFO - Categorical columns: ['Crop', 'Region']
2025-03-20 12:52:53,562 - INFO - Numerical columns: ['Rainfall_mm', 'Avg_Temperature_C', 'Production_Tonnes', 'MSP', 'Export_Demand_Tonnes', 'Prev_Year_Price']
2025-03-20 12:52:53,567 - INFO - Data split into training and testing sets.
2025-03-20 12:52:56,120 - INFO - Random Forest Regression model trained and predictions made.
2025-03-20 12:52:56,122 - INFO - Random Forest Regression - R2: 0.9253, MAE: 183.4073, MSE: 50941.9895, RMSE: 225.7033
2025-03-20 12:52:56,140 - INFO - Random Forest Regression - Regression confusion matrix:
Predicted Bin   0   1   2   3   4
Actual Bin                       
0              49  10   0   0   0
1               1  81  13   0   0
2               0   8  34  21   0
3               0   0   8  35  18
4               0   0   0   8  22
2025-03-20 12:52:56,160 - INFO - \u2705 Random Forest model and preprocessing objects saved successfully.
2025-03-20 13:02:07,790 - INFO - Dataset loaded successfully.
2025-03-20 13:02:07,793 - INFO - Features and target variable separated.
2025-03-20 13:02:07,793 - INFO - Categorical columns: ['Crop', 'Region']
2025-03-20 13:02:07,793 - INFO - Numerical columns: ['Rainfall_mm', 'Avg_Temperature_C', 'Production_Tonnes', 'MSP', 'Export_Demand_Tonnes', 'Prev_Year_Price']
2025-03-20 13:02:07,797 - INFO - Data split into training and testing sets.
2025-03-20 13:02:11,698 - INFO - Random Forest Regression model trained and predictions made.
2025-03-20 13:02:11,699 - INFO - Random Forest Regression - R2: 0.9253, MAE: 183.4073, MSE: 50941.9895, RMSE: 225.7033
2025-03-20 13:02:11,706 - INFO - Random Forest Regression - Regression confusion matrix:
Predicted Bin   0   1   2   3   4
Actual Bin                       
0              49  10   0   0   0
1               1  81  13   0   0
2               0   8  34  21   0
3               0   0   8  35  18
4               0   0   0   8  22
2025-03-20 13:02:11,728 - INFO - \u2705 Random Forest model and preprocessing objects saved successfully.
